Workbook

Sheet 汇总
A1: WWC 3.0 与 5.0 评级对照汇总
A2: 单一被试共 45 篇（A组43篇 + 户秀美2025、张晓敏2026）；组间设计共 9 篇（B组8篇 + 沙鹏2023）。计数均由公式从后两张表自动统计。视觉分析的证据评级为初判，需第二评分者核对。
A4: 一、单一被试：各版本评级篇数
A5: 评级 | B5: 3.0 | C5: 5.0
A6: 无保留 | B6: =COUNTIF(单一被试!$J$2:$J$46,"无保留") -> 13 | C6: =COUNTIF(单一被试!$K$2:$K$46,"无保留") -> 5
A7: 有保留 | B7: =COUNTIF(单一被试!$J$2:$J$46,"有保留") -> 22 | C7: =COUNTIF(单一被试!$K$2:$K$46,"有保留") -> 30
A8: 不达标 | B8: =COUNTIF(单一被试!$J$2:$J$46,"不达标") -> 10 | C8: =COUNTIF(单一被试!$K$2:$K$46,"不达标") -> 10
A9: 达标合计（无保留+有保留） | B9: =B6+B7 -> 35 | C9: =C6+C7 -> 35
A10: 两版评级一致 / 不一致 | B10: =COUNTIF(单一被试!$L$2:$L$46,"一致") -> 33 | C10: =COUNTIF(单一被试!$L$2:$L$46,"不一致") -> 12 | D10: ←左：一致；右：不一致
A12: 二、单一被试：3.0（行）× 5.0（列）交叉表
A13: 3.0 \ 5.0 | B13: 无保留 | C13: 有保留 | D13: 不达标 | E13: 合计
A14: 无保留 | B14: =COUNTIFS(单一被试!$J$2:$J$46,"无保留",单一被试!$K$2:$K$46,"无保留") -> 4 | C14: =COUNTIFS(单一被试!$J$2:$J$46,"无保留",单一被试!$K$2:$K$46,"有保留") -> 9 | D14: =COUNTIFS(单一被试!$J$2:$J$46,"无保留",单一被试!$K$2:$K$46,"不达标") -> 0 | E14: =SUM(B14:D14) -> 13
A15: 有保留 | B15: =COUNTIFS(单一被试!$J$2:$J$46,"有保留",单一被试!$K$2:$K$46,"无保留") -> 1 | C15: =COUNTIFS(单一被试!$J$2:$J$46,"有保留",单一被试!$K$2:$K$46,"有保留") -> 20 | D15: =COUNTIFS(单一被试!$J$2:$J$46,"有保留",单一被试!$K$2:$K$46,"不达标") -> 1 | E15: =SUM(B15:D15) -> 22
A16: 不达标 | B16: =COUNTIFS(单一被试!$J$2:$J$46,"不达标",单一被试!$K$2:$K$46,"无保留") -> 0 | C16: =COUNTIFS(单一被试!$J$2:$J$46,"不达标",单一被试!$K$2:$K$46,"有保留") -> 1 | D16: =COUNTIFS(单一被试!$J$2:$J$46,"不达标",单一被试!$K$2:$K$46,"不达标") -> 9 | E16: =SUM(B16:D16) -> 10
A17: 合计 | B17: =SUM(B14:B16) -> 5 | C17: =SUM(C14:C16) -> 30 | D17: =SUM(D14:D16) -> 10 | E17: =SUM(E14:E16) -> 45
A19: 三、3.0 证据评级（仅3.0达标的研究，视觉分析初判）
A20: 证据等级 | B20: 篇数
A21: 强证据 | B21: =COUNTIFS(单一被试!$J$2:$J$46,"<>不达标",单一被试!$H$2:$H$46,"强*") -> 21
A22: 中等证据 | B22: =COUNTIFS(单一被试!$J$2:$J$46,"<>不达标",单一被试!$H$2:$H$46,"中等*") -> 13
A23: 按条件分别评定（008A交替处理：加重毯无证据、工作盒强证据） | B23: =COUNTIFS(单一被试!$J$2:$J$46,"<>不达标",单一被试!$H$2:$H$46,"*无证据*") -> 1
A24: 合计 | B24: =SUM(B21:B23) -> 35 | C24: =IF(B24=B9,"与3.0达标篇数相符","核对") -> 与3.0达标篇数相符
A26: 四、组间设计：评级篇数（3.0与5.0结果相同，差别只在流失边界的选择）
A27: 评级 | B27: 宽松/乐观边界 | C27: 保守/谨慎边界
A28: 无保留 | B28: =COUNTIF(组间设计!$I$2:$I$10,"无保留") -> 6 | C28: =COUNTIF(组间设计!$J$2:$J$10,"无保留") -> 4
A29: 有保留 | B29: =COUNTIF(组间设计!$I$2:$I$10,"有保留") -> 0 | C29: =COUNTIF(组间设计!$J$2:$J$10,"有保留") -> 1
A30: 不达标 | B30: =COUNTIF(组间设计!$I$2:$I$10,"不达标") -> 3 | C30: =COUNTIF(组间设计!$J$2:$J$10,"不达标") -> 4
A31: 达标合计 | B31: =B28+B29 -> 6 | C31: =C28+C29 -> 5
A33: 五、两版结果不一致的原因（单一被试）
A34: 原因 | B34: 涉及研究 | C34: 变化方向
A35: 5.0 要求首个基线≥6个数据点才能"无保留"（3.0 是每阶段≥5点） | B35: 005A、007A、027A、029A、032A、037A、040A、043A | C35: 3.0 无保留 → 5.0 有保留
A36: 5.0 新增"最小治疗方向基线趋势"检查（初始基线后3点与其余点比较，NAP>.85即不合格） | B36: 002A | C36: 3.0 无保留 → 5.0 有保留
A37: 5.0 多探测设计要求首3次会话内至少有一次所有层"垂直重叠"（3.0 只要求每层各有1个探测点） | B37: 012A | C37: 3.0 有保留 → 5.0 不达标
A38: 5.0 新增"其他单一被试设计"条款，可按公认规范评定手册未列出的设计（3.0 只认撤回、多基线/多探测、交替处理） | B38: 017A（重复习得设计） | C38: 3.0 不达标 → 5.0 有保留
A39: 5.0 新增零变异例外：≥3个完全相同的数据点即可视为数据量足够 | B39: 046A | C39: 3.0 有保留 → 5.0 无保留
A41: 六、两版共同的不达标原因（单一被试，两版均不达标）
A42: 多探测设计的探测点要求不满足（首3次会话无探测点、他层进入干预时无探测点等）：015A、023A、034A、038A、045A
A43: 基线或干预阶段≤2个数据点：031A
A44: 观察者一致性未覆盖每一阶段：014A
A45: 非同时多基线：041A
A46: 设计类型无法提供3次效果展示（变换条件设计）：026A
...

Sheet 单一被试
A1: 文件 | B1: 设计 | C1: 3.0 评级 | D1: 3.0 不达标条目 | E1: 5.0 评级 | F1: 5.0 不达标条目 | G1: 两版不一致的原因 | H1: 3.0 证据评级（视觉分析，初判） | I1: 备注 | J1: 3.0类别 | K1: 5.0类别 | L1: 两版是否一致
A2: 001-A 多成分同伴介入干预对孤独症谱系障碍学前儿童社会沟通的影响 | B2: 多探测(3对) | C2: 有保留 | D2: Olin、Titus干预前3次会话内仅2个探测点 | E2: 有保留 | F2: 同左（干预前未连续3个探测点） | G2: — | H2: 中等(初判；Wilmer效果滞后) | I2: IOA 30%，社交发起87%；无脚本言语IOA 75%不达标（次要结局） | J2: 有保留 | K2: 有保留 | L2: =IF(J2=K2,"一致","不一致") -> 一致
A3: 002-A 学前课堂中的同伴介入共同注意干预 | B3: 设计1多基线(4人)+设计2多探测(3人) | C3: 无保留(设计1) | D3: 设计2：首3次会话及干预前探测不足→有保留 | E3: 有保留 | F3: 设计1：Arthur、Jason基线有治疗方向趋势(NAP>.85)，不满足"最小基线趋势" | G3: 5.0新增基线趋势检查 | H3: 强(初判，设计1) | I3: 仅4名按教育鉴定为ASD；IOA基线57%、干预35.4% | J3: 无保留 | K3: 有保留 | L3: =IF(J3=K3,"一致","不一致") -> 不一致
A4: 003-A 通过合作性户外游戏增加孤独症学前儿童的社会互动 | B4: 多基线(3个班) | C4: 有保留 | D4: Pre-K干预期仅4个点 | E4: 有保留 | F4: Pre-K基线5点(<6)、干预4点 | G4: — | H4: 中等(初判；PS层基线波动大、重叠多) | I4: IOA 38%，基线88%/干预94% | J4: 有保留 | K4: 有保留 | L4: =IF(J4=K4,"一致","不一致") -> 一致
A5: 005-A 超越行为形态：关注孤独症学生社交技能训练的功能性影响 | B5: 多基线(3人) | C5: 无保留 | D5: — | E5: 有保留 | F5: Juan首个基线仅5点(<6) | G5: 5.0基线需≥6点 | H5: 中等(初判；Doug、Elli基线波动大且与干预期重叠) | I5: IOA 35%，社交发声91%；同伴回应IOA 74%（次要结局） | J5: 无保留 | K5: 有保留 | L5: =IF(J5=K5,"一致","不一致") -> 不一致
A6: 006-A 提升孤独症谱系障碍学前学生的数感理解 | B6: 多探测(3人) | C6: 有保留 | D6: Laura干预期仅4点 | E6: 有保留 | F6: Laura干预期仅4点 | G6: — | H6: 强(初判) | I6: IOA 50%探测，均≥95% | J6: 有保留 | K6: 有保留 | L6: =IF(J6=K6,"一致","不一致") -> 一致
A7: 007-A 不同教学形式与环境下同伴支持安排对重度障碍学生的影响 | B7: 多探测(3人) | C7: 无保留 | D7: — | E7: 有保留 | F7: Adrian首个基线仅5点(<6) | G7: 5.0基线需≥6点 | H7: 强(初判，互动) | I7: 仅Adrian为ASD；IOA 27.3%，均>90% | J7: 无保留 | K7: 有保留 | L7: =IF(J7=K7,"一致","不一致") -> 不一致
A8: 008-A 简报：加重毯对一名孤独症谱系障碍学生参与度的影响 | B8: 交替处理(1人；基线→加重毯/工作盒/基线交替) | C8: 无保留 | D8: — | E8: 无保留 | F8: — | G8: — | H8: 加重毯vs基线：无证据；工作盒vs基线：强(初判) | I8: 各条件≥5点、连续同条件≤2；IOA 33–60%，88.8% | J8: 无保留 | K8: 无保留 | L8: =IF(J8=K8,"一致","不一致") -> 一致
A9: 009-A 教导幼儿向孤独症谱系障碍同伴发出游戏邀请 | B9: 多探测(3对) | C9: 有保留 | D9: Amber/Regina基线仅3点；Milo/Xane干预4点；Enzo、Xane干预前3次会话内仅1个探测点 | E9: 有保留 | F9: 首个基线<6点；干预前探测不足3个 | G9: — | H9: 强(初判，ASD儿童回应) | I9: 主要因变量为同伴发起；ASD儿童回应为次要结局；IOA 33%，87–97% | J9: 有保留 | K9: 有保留 | L9: =IF(J9=K9,"一致","不一致") -> 一致
A10: 010-A 结合偏好活动与同伴支持以增加孤独症谱系障碍学前儿童与典型发展同伴之间的社会互动 | B10: 多探测跨3名同伴+A-B-A-B+C | C10: 有保留 | D10: 第二基线(A2)各层仅3点；两个干预期不是同一干预(B 与 B+C) | E10: 有保留 | F10: 首个基线<6点；A2仅3点 | G10: — | H10: 强(初判，社交发起) | I10: 两名ASD儿童(Yaoyao、Baobao)各一组图；IOA≥30%，>80% | J10: 有保留 | K10: 有保留 | L10: =IF(J10=K10,"一致","不一致") -> 一致
A11: 011-A 运用视觉日程表和工作系统提高普通班孤独症谱系学生的任务专注行为 | B11: 多基线(4人) | C11: 有保留 | D11: Edward、Sam干预期仅4点；Sam基线仅5点且始于第20次会话（James已进入干预） | E11: 有保留 | F11: Sam违反同时性(James干预前Sam无基线数据)→去掉Sam后以其余3层评；Edward干预4点 | G11: — | H11: 中等(初判；Sam有非效果，James基线有上升点) | I11: 两版说明：3.0未明确同时性要求；5.0去掉Sam后仍有保留；IOA 27–33%，>87% | J11: 有保留 | K11: 有保留 | L11: =IF(J11=K11,"一致","不一致") -> 一致
A12: 012-A 运用结构分析指导重度障碍高中生的同伴支持安排 | B12: 多探测(3人) | C12: 有保留 | D12: 首3次会话每层≥1个探测点但非连续3个；干预前3次会话内探测不足3个 | E12: 不达标(初判) | F12: 前3次会话中没有三层同时有探测点的会话(John 2；Tyler、Richard 1、3) | G12: 5.0要求首3次会话内"垂直重叠" | H12: 中等(初判；Richard效果弱) | I12: 仅Tyler、Richard为ASD；IOA 37.6%，97.7% | J12: 有保留 | K12: 不达标 | L12: =IF(J12=K12,"一致","不一致") -> 不一致
A13: 013-A 同伴介入干预在提升孤独症学生写作技能方面的有效性 | B13: 多基线跨3种行为(1人) | C13: 有保留 | D13: 主谓一致基线仅4点 | E13: 有保留 | F13: 首个基线<6点 | G13: — | H13: 强(初判) | I13: IOA 25%会话，95%；未说明各阶段均有IOA（按作者表述视为满足） | J13: 有保留 | K13: 有保留 | L13: =IF(J13=K13,"一致","不一致") -> 一致
... A46: 张晓敏2026 融合教育环境中人际同步音乐活动促进孤独症幼儿社会交往的干预研究（中文） | B46: 跨被试多探测(3人，实际每次均测) | C46: 有保留 | D46: 小宇基线仅3点 | E46: 有保留 | F46: 小宇基线3点(<6且非零变异) | G46: — | H46: 强(初判) | I46: IOA基线/干预/维持各30%，95–98% | J46: 有保留 | K46: 有保留 | L46: =IF(J46=K46,"一致","不一致") -> 一致

Sheet 组间设计
A1: 文件 | B1: 设计 | C1: 3.0 评级 | D1: 3.0 不达标条目 | E1: 5.0 评级 | F1: 5.0 不达标条目 | G1: 两版不一致的原因 | H1: 备注 | I1: 类别（宽松/乐观流失边界） | J1: 类别（保守/谨慎流失边界）
A2: 001-B 实施支持对公立学校孤独症儿童社会参与干预应用的影响 | B2: 整群RCT(12所学校；RR培训 vs RR培训+实施支持) | C2: 无保留 | D2: — | E2: 无保留 | F2: — | G2: — | H2: 两组都接受RR，对比的是"实施支持"本身，不是干预vs无干预；儿童在学校随机化前已招募，流失极少(仅1人搬走) | I2: 无保留 | J2: 无保留
A3: 002-B 孤独症谱系障碍青少年与校内社交技能小组：比较干预环境和同伴构成的随机试验 | B3: 个体RCT(70人；社交技能组 vs 参与组) | C3: 宽松边界：无保留；保守边界：不达标 | D3: 总流失11.4%、差异流失9.5%(参与组6/38，技能组2/32)；保守边界下属高流失，且未以效应量形式报告分析样本基线等同 | E3: 乐观边界：无保留；谨慎边界(默认)：不达标 | F3: 同左 | G3: — | H3: 两版说明：一致(都取决于流失边界)；两种干预对比，无未干预对照；部分被试ADOS未达谱系标准 | I3: 无保留 | J3: 不达标
A4: 003-B 加速实现公平：句法引导对孤独症儿童融合教育及可持续发展目标4的因果影响 | B4: 准实验(实验组18 vs 对照组17) | C4: 不达标 | D4: 未报告对照组前测，无法确认基线等同 | E4: 不达标 | F4: 同左 | G4: — | H4: — | I4: 不达标 | J4: 不达标
A5: 005-B 普通教育课堂中孤独症学生的学业与社会参与结果：实施融合实践以提升生活质量所面临的挑战 | B5: 整群RCT(32所学校，三臂：SDLMI+PS / PS / SDLMI) | C5: 不达标 | D5: 68人中仅59人有观察数据，各组流失未报告→按高流失处理；结局无前测，无法证明基线等同 | E5: 不达标 | F5: 同左；5.0还明确要求：学校随机化后才确定的学生须证明基线等同 | G5: — | H5: 无未干预对照组 | I5: 不达标 | J5: 不达标
A6: 006-B 基于幼儿园的普适性情绪教育项目对3至5岁孤独症谱系儿童的有效性 | B6: 整群RCT中的ASD亚组(25所学校；干预34 vs 对照15) | C6: 不达标 | D6: 流失无法计算；前测ECAQ干预组65.8 vs 对照组76.5，差约0.58 SD(>0.25) | E6: 不达标 | F6: 同左 | G6: — | H6: — | I6: 不达标 | J6: 不达标
A7: 007-B I-SOCIALISE：探究在学校环境中参加乐高疗法（“积木游戏疗法”）俱乐部的孤独症儿童社会能力与社会孤立状况的整群随机对照试验结果 | B7: 整群RCT(98所学校；乐高治疗+常规支持 vs 常规支持) | C7: 宽松边界：无保留；保守边界：有保留(初判) | D7: 学校层流失低(总11.2%、差异2.5%)；儿童层20周流失12%、差异8.4%，保守边界下属高流失，需分析样本基线等同(全样本基线差0.06 SD，分析已调整前测) | E7: 乐观边界：无保留；谨慎边界：有保留(初判) | F7: 同左 | G7: — | H7: 两版说明：一致(都取决于流失边界)；分析样本的基线数据未单独报告，按全样本差异判断 | I7: 无保留 | J7: 有保留
A8: 008-B 小学柔道与空手道作为促进孤独症儿童社会融合的手段 | B8: 随机分班(31个班；柔道 vs 空手道) | C8: 无保留(初判) | D8: 无流失；随机化描述简略；教练人数未报告(若每个项目只有1名教练则构成混淆→不达标) | E8: 无保留(初判) | F8: 同左 | G8: — | H8: 两种干预对比，无未干预对照；原文只报告组内前后测变化 | I8: 无保留 | J8: 无保留
A9: 009-B “重塑课间休息”干预改善孤独症谱系障碍儿童在校同伴互动：多地点随机试验 | B9: RCT(80人；RR vs 候补对照) | C9: 无保留 | D9: 流失约2.5% | E9: 无保留 | F9: — | G9: — | H9: 随访只在2个地点收集(计划内) | I9: 无保留 | J9: 无保留
A10: 沙鹏2023 基于同伴介入法的气排球运动干预对随班就读孤独症儿童社交能力的影响（中文） | B10: 个体RCT(36人，18/18，随机数表) | C10: 无保留(初判) | D10: 无流失；前测无差异(η²≤.006) | E10: 无保留(初判) | F10: 同左 | G10: — | H10: 需核对：若实验组由同一名教练集中带一个组，可能被视为"n=1"混淆；对照组接受同频常规社交干预 | I10: 无保留 | J10: 无保留
